<?xml version="1.0" ?>
<!--
  THIS FILE IS AUTO-GENERATED FROM AN ERB TEMPLATE

  see instructions in 'path_to_ws/src/aic/aic_assets/scripts/cable.sdf.erb'
-->
<sdf version="1.9">
  <model name="cable">
    <link name="cable_end_0">
      <pose>0.000000 0.000000 0.000000 0.000000 -0.000000 0.000000</pose>
      <inertial>
        <pose>0.000000 0.000000 0.000000 0.000000 -0.000000 0.000000</pose>
        <mass>0.0375</mass>
        <inertia>
          <ixx>0.010000</ixx>
          <ixy>0.000000</ixy>
          <ixz>0.000000</ixz>
          <iyy>0.010000</iyy>
          <iyz>0.000000</iyz>
          <izz>0.010000</izz>
        </inertia>
      </inertial>
      <collision name="base_collision">
        <pose>0.000000 0.000000 0.000000 0.000000 0.000000 0.000000</pose>
        <geometry>
          <sphere>
            <radius>0.002</radius>
          </sphere>
        </geometry>
      </collision>
      <visual name="base_vis">
        <pose>0.000000 0.000000 0.000000 0.000000 0.000000 0.000000</pose>
        <geometry>
          <sphere>
            <radius>0.002</radius>
          </sphere>
        </geometry>
        <material>
          <diffuse>0.6 0.6 0.0</diffuse>
          <specular>0.2 0.2 0.2</specular>
          <pbr>
            <metal>
              <roughness>0.05</roughness>
              <metalness>0.01</metalness>
            </metal>
          </pbr>
        </material>
      </visual>
    </link>
    <joint name="joint_end_0" type="ball">
      <pose>0.00000 0.000000 -0.03125 0.000000 0 0.000000</pose>
      <child>link_1</child>
      <parent>cable_end_0</parent>
      <axis>
        <dynamics>
          <damping>1.0</damping>
          <spring_stiffness>1.0</spring_stiffness>
        </dynamics>
      </axis>
    </joint>
    <link name="link_1">
      <pose>0.03125 0.000000 0.000000 0.000000 1.570790 0.000000</pose>
      <inertial>
        <pose>0.000000 0.000000 0.000000 0.000000 -0.000000 0.000000</pose>
        <mass>0.0375</mass>
        <inertia>
          <ixx>0.010000</ixx>
          <ixy>0.000000</ixy>
          <ixz>0.000000</ixz>
          <iyy>0.010000</iyy>
          <iyz>0.000000</iyz>
          <izz>0.010000</izz>
        </inertia>
      </inertial>
      <collision name="link_1_collision">
        <pose>0.00000 0.000000 0.000000 0.000000 0 0.000000</pose>
        <geometry>
          <cylinder>
            <length>0.0625</length>
            <radius>0.002</radius>
          </cylinder>
        </geometry>
      </collision>
      <visual name="link_1_vis">
        <pose>0.00000 0.000000 0.000000 0.000000 0 0.000000</pose>
        <geometry>
          <cylinder>
            <length>0.0625</length>
            <radius>0.002</radius>
          </cylinder>
        </geometry>
        <material>
          <diffuse>0.6 0.6 0.0</diffuse>
          <specular>0.2 0.2 0.2</specular>
          <pbr>
            <metal>
              <roughness>0.05</roughness>
              <metalness>0.01</metalness>
            </metal>
          </pbr>
        </material>
      </visual>
      <collision name="sphere_1_collision">
        <pose>0.000000 0.000000 0.03125 0.000000 -0.000000 0.000000</pose>
        <geometry>
          <sphere>
            <radius>0.002</radius>
          </sphere>
        </geometry>
      </collision>
      <visual name="sphere_1_vis">
        <pose>0.000000 0.000000 0.03125 0.000000 -0.000000 0.000000</pose>
        <geometry>
          <sphere>
            <radius>0.002</radius>
          </sphere>
        </geometry>
        <material>
          <diffuse>0.6 0.6 0.0</diffuse>
          <specular>0.2 0.2 0.2</specular>
          <pbr>
            <metal>
              <roughness>0.05</roughness>
              <metalness>0.01</metalness>
            </metal>
          </pbr>
        </material>
      </visual>
    </link>
    <link name="link_2">
      <pose>0.09375 0.000000 0.000000 0.000000 1.570790 0.000000</pose>
      <inertial>
        <pose>0.000000 0.000000 0.000000 0.000000 -0.000000 0.000000</pose>
        <mass>0.0375</mass>
        <inertia>
          <ixx>0.010000</ixx>
          <ixy>0.000000</ixy>
          <ixz>0.000000</ixz>
          <iyy>0.010000</iyy>
          <iyz>0.000000</iyz>
          <izz>0.010000</izz>
        </inertia>
      </inertial>
      <collision name="link_2_collision">
        <pose>0.00000 0.000000 0.000000 0.000000 0 0.000000</pose>
        <geometry>
          <cylinder>
            <length>0.0625</length>
            <radius>0.002</radius>
          </cylinder>
        </geometry>
      </collision>
      <visual name="link_2_vis">
        <pose>0.00000 0.000000 0.000000 0.000000 0 0.000000</pose>
        <geometry>
          <cylinder>
            <length>0.0625</length>
            <radius>0.002</radius>
          </cylinder>
        </geometry>
        <material>
          <diffuse>0.6 0.6 0.0</diffuse>
          <specular>0.2 0.2 0.2</specular>
          <pbr>
            <metal>
              <roughness>0.05</roughness>
              <metalness>0.01</metalness>
            </metal>
          </pbr>
        </material>
      </visual>
      <collision name="sphere_2_collision">
        <pose>0.000000 0.000000 0.03125 0.000000 -0.000000 0.000000</pose>
        <geometry>
          <sphere>
            <radius>0.002</radius>
          </sphere>
        </geometry>
      </collision>
      <visual name="sphere_2_vis">
        <pose>0.000000 0.000000 0.03125 0.000000 -0.000000 0.000000</pose>
        <geometry>
          <sphere>
            <radius>0.002</radius>
          </sphere>
        </geometry>
        <material>
          <diffuse>0.6 0.6 0.0</diffuse>
          <specular>0.2 0.2 0.2</specular>
          <pbr>
            <metal>
              <roughness>0.05</roughness>
              <metalness>0.01</metalness>
            </metal>
          </pbr>
        </material>
      </visual>
    </link>
    <link name="link_3">
      <pose>0.15625 0.000000 0.000000 0.000000 1.570790 0.000000</pose>
      <inertial>
        <pose>0.000000 0.000000 0.000000 0.000000 -0.000000 0.000000</pose>
        <mass>0.0375</mass>
        <inertia>
          <ixx>0.010000</ixx>
          <ixy>0.000000</ixy>
          <ixz>0.000000</ixz>
          <iyy>0.010000</iyy>
          <iyz>0.000000</iyz>
          <izz>0.010000</izz>
        </inertia>
      </inertial>
      <collision name="link_3_collision">
        <pose>0.00000 0.000000 0.000000 0.000000 0 0.000000</pose>
        <geometry>
          <cylinder>
            <length>0.0625</length>
            <radius>0.002</radius>
          </cylinder>
        </geometry>
      </collision>
      <visual name="link_3_vis">
        <pose>0.00000 0.000000 0.000000 0.000000 0 0.000000</pose>
        <geometry>
          <cylinder>
            <length>0.0625</length>
            <radius>0.002</radius>
          </cylinder>
        </geometry>
        <material>
          <diffuse>0.6 0.6 0.0</diffuse>
          <specular>0.2 0.2 0.2</specular>
          <pbr>
            <metal>
              <roughness>0.05</roughness>
              <metalness>0.01</metalness>
            </metal>
          </pbr>
        </material>
      </visual>
      <collision name="sphere_3_collision">
        <pose>0.000000 0.000000 0.03125 0.000000 -0.000000 0.000000</pose>
        <geometry>
          <sphere>
            <radius>0.002</radius>
          </sphere>
        </geometry>
      </collision>
      <visual name="sphere_3_vis">
        <pose>0.000000 0.000000 0.03125 0.000000 -0.000000 0.000000</pose>
        <geometry>
          <sphere>
            <radius>0.002</radius>
          </sphere>
        </geometry>
        <material>
          <diffuse>0.6 0.6 0.0</diffuse>
          <specular>0.2 0.2 0.2</specular>
          <pbr>
            <metal>
              <roughness>0.05</roughness>
              <metalness>0.01</metalness>
            </metal>
          </pbr>
        </material>
      </visual>
    </link>
    <link name="link_4">
      <pose>0.21875 0.000000 0.000000 0.000000 1.570790 0.000000</pose>
      <inertial>
        <pose>0.000000 0.000000 0.000000 0.000000 -0.000000 0.000000</pose>
        <mass>0.0375</mass>
        <inertia>
          <ixx>0.010000</ixx>
          <ixy>0.000000</ixy>
          <ixz>0.000000</ixz>
          <iyy>0.010000</iyy>
          <iyz>0.000000</iyz>
          <izz>0.010000</izz>
        </inertia>
      </inertial>
      <collision name="link_4_collision">
        <pose>0.00000 0.000000 0.000000 0.000000 0 0.000000</pose>
        <geometry>
          <cylinder>
            <length>0.0625</length>
            <radius>0.002</radius>
          </cylinder>
        </geometry>
      </collision>
      <visual name="link_4_vis">
        <pose>0.00000 0.000000 0.000000 0.000000 0 0.000000</pose>
        <geometry>
          <cylinder>
            <length>0.0625</length>
            <radius>0.002</radius>
          </cylinder>
        </geometry>
        <material>
          <diffuse>0.6 0.6 0.0</diffuse>
          <specular>0.2 0.2 0.2</specular>
          <pbr>
            <metal>
              <roughness>0.05</roughness>
              <metalness>0.01</metalness>
            </metal>
          </pbr>
        </material>
      </visual>
      <collision name="sphere_4_collision">
        <pose>0.000000 0.000000 0.03125 0.000000 -0.000000 0.000000</pose>
        <geometry>
          <sphere>
            <radius>0.002</radius>
          </sphere>
        </geometry>
      </collision>
      <visual name="sphere_4_vis">
        <pose>0.000000 0.000000 0.03125 0.000000 -0.000000 0.000000</pose>
        <geometry>
          <sphere>
            <radius>0.002</radius>
          </sphere>
        </geometry>
        <material>
          <diffuse>0.6 0.6 0.0</diffuse>
          <specular>0.2 0.2 0.2</specular>
          <pbr>
            <metal>
              <roughness>0.05</roughness>
              <metalness>0.01</metalness>
            </metal>
          </pbr>
        </material>
      </visual>
    </link>
    <link name="link_5">
      <pose>0.28125 0.000000 0.000000 0.000000 1.570790 0.000000</pose>
      <inertial>
        <pose>0.000000 0.000000 0.000000 0.000000 -0.000000 0.000000</pose>
        <mass>0.0375</mass>
        <inertia>
          <ixx>0.010000</ixx>
          <ixy>0.000000</ixy>
          <ixz>0.000000</ixz>
          <iyy>0.010000</iyy>
          <iyz>0.000000</iyz>
          <izz>0.010000</izz>
        </inertia>
      </inertial>
      <collision name="link_5_collision">
        <pose>0.00000 0.000000 0.000000 0.000000 0 0.000000</pose>
        <geometry>
          <cylinder>
            <length>0.0625</length>
            <radius>0.002</radius>
          </cylinder>
        </geometry>
      </collision>
      <visual name="link_5_vis">
        <pose>0.00000 0.000000 0.000000 0.000000 0 0.000000</pose>
        <geometry>
          <cylinder>
            <length>0.0625</length>
            <radius>0.002</radius>
          </cylinder>
        </geometry>
        <material>
          <diffuse>0.6 0.6 0.0</diffuse>
          <specular>0.2 0.2 0.2</specular>
          <pbr>
            <metal>
              <roughness>0.05</roughness>
              <metalness>0.01</metalness>
            </metal>
          </pbr>
        </material>
      </visual>
      <collision name="sphere_5_collision">
        <pose>0.000000 0.000000 0.03125 0.000000 -0.000000 0.000000</pose>
        <geometry>
          <sphere>
            <radius>0.002</radius>
          </sphere>
        </geometry>
      </collision>
      <visual name="sphere_5_vis">
        <pose>0.000000 0.000000 0.03125 0.000000 -0.000000 0.000000</pose>
        <geometry>
          <sphere>
            <radius>0.002</radius>
          </sphere>
        </geometry>
        <material>
          <diffuse>0.6 0.6 0.0</diffuse>
          <specular>0.2 0.2 0.2</specular>
          <pbr>
            <metal>
              <roughness>0.05</roughness>
              <metalness>0.01</metalness>
            </metal>
          </pbr>
        </material>
      </visual>
    </link>
    <link name="link_6">
      <pose>0.34375 0.000000 0.000000 0.000000 1.570790 0.000000</pose>
      <inertial>
        <pose>0.000000 0.000000 0.000000 0.000000 -0.000000 0.000000</pose>
        <mass>0.0375</mass>
        <inertia>
          <ixx>0.010000</ixx>
          <ixy>0.000000</ixy>
          <ixz>0.000000</ixz>
          <iyy>0.010000</iyy>
          <iyz>0.000000</iyz>
          <izz>0.010000</izz>
        </inertia>
      </inertial>
      <collision name="link_6_collision">
        <pose>0.00000 0.000000 0.000000 0.000000 0 0.000000</pose>
        <geometry>
          <cylinder>
            <length>0.0625</length>
            <radius>0.002</radius>
          </cylinder>
        </geometry>
      </collision>
      <visual name="link_6_vis">
        <pose>0.00000 0.000000 0.000000 0.000000 0 0.000000</pose>
        <geometry>
          <cylinder>
            <length>0.0625</length>
            <radius>0.002</radius>
          </cylinder>
        </geometry>
        <material>
          <diffuse>0.6 0.6 0.0</diffuse>
          <specular>0.2 0.2 0.2</specular>
          <pbr>
            <metal>
              <roughness>0.05</roughness>
              <metalness>0.01</metalness>
            </metal>
          </pbr>
        </material>
      </visual>
      <collision name="sphere_6_collision">
        <pose>0.000000 0.000000 0.03125 0.000000 -0.000000 0.000000</pose>
        <geometry>
          <sphere>
            <radius>0.002</radius>
          </sphere>
        </geometry>
      </collision>
      <visual name="sphere_6_vis">
        <pose>0.000000 0.000000 0.03125 0.000000 -0.000000 0.000000</pose>
        <geometry>
          <sphere>
            <radius>0.002</radius>
          </sphere>
        </geometry>
        <material>
          <diffuse>0.6 0.6 0.0</diffuse>
          <specular>0.2 0.2 0.2</specular>
          <pbr>
            <metal>
              <roughness>0.05</roughness>
              <metalness>0.01</metalness>
            </metal>
          </pbr>
        </material>
      </visual>
    </link>
    <link name="link_7">
      <pose>0.40625 0.000000 0.000000 0.000000 1.570790 0.000000</pose>
      <inertial>
        <pose>0.000000 0.000000 0.000000 0.000000 -0.000000 0.000000</pose>
        <mass>0.0375</mass>
        <inertia>
          <ixx>0.010000</ixx>
          <ixy>0.000000</ixy>
          <ixz>0.000000</ixz>
          <iyy>0.010000</iyy>
          <iyz>0.000000</iyz>
          <izz>0.010000</izz>
        </inertia>
      </inertial>
      <collision name="link_7_collision">
        <pose>0.00000 0.000000 0.000000 0.000000 0 0.000000</pose>
        <geometry>
          <cylinder>
            <length>0.0625</length>
            <radius>0.002</radius>
          </cylinder>
        </geometry>
      </collision>
      <visual name="link_7_vis">
        <pose>0.00000 0.000000 0.000000 0.000000 0 0.000000</pose>
        <geometry>
          <cylinder>
            <length>0.0625</length>
            <radius>0.002</radius>
          </cylinder>
        </geometry>
        <material>
          <diffuse>0.6 0.6 0.0</diffuse>
          <specular>0.2 0.2 0.2</specular>
          <pbr>
            <metal>
              <roughness>0.05</roughness>
              <metalness>0.01</metalness>
            </metal>
          </pbr>
        </material>
      </visual>
      <collision name="sphere_7_collision">
        <pose>0.000000 0.000000 0.03125 0.000000 -0.000000 0.000000</pose>
        <geometry>
          <sphere>
            <radius>0.002</radius>
          </sphere>
        </geometry>
      </collision>
      <visual name="sphere_7_vis">
        <pose>0.000000 0.000000 0.03125 0.000000 -0.000000 0.000000</pose>
        <geometry>
          <sphere>
            <radius>0.002</radius>
          </sphere>
        </geometry>
        <material>
          <diffuse>0.6 0.6 0.0</diffuse>
          <specular>0.2 0.2 0.2</specular>
          <pbr>
            <metal>
              <roughness>0.05</roughness>
              <metalness>0.01</metalness>
            </metal>
          </pbr>
        </material>
      </visual>
    </link>
    <link name="link_8">
      <pose>0.46875 0.000000 0.000000 0.000000 1.570790 0.000000</pose>
      <inertial>
        <pose>0.000000 0.000000 0.000000 0.000000 -0.000000 0.000000</pose>
        <mass>0.0375</mass>
        <inertia>
          <ixx>0.010000</ixx>
          <ixy>0.000000</ixy>
          <ixz>0.000000</ixz>
          <iyy>0.010000</iyy>
          <iyz>0.000000</iyz>
          <izz>0.010000</izz>
        </inertia>
      </inertial>
      <collision name="link_8_collision">
        <pose>0.00000 0.000000 0.000000 0.000000 0 0.000000</pose>
        <geometry>
          <cylinder>
            <length>0.0625</length>
            <radius>0.002</radius>
          </cylinder>
        </geometry>
      </collision>
      <visual name="link_8_vis">
        <pose>0.00000 0.000000 0.000000 0.000000 0 0.000000</pose>
        <geometry>
          <cylinder>
            <length>0.0625</length>
            <radius>0.002</radius>
          </cylinder>
        </geometry>
        <material>
          <diffuse>0.6 0.6 0.0</diffuse>
          <specular>0.2 0.2 0.2</specular>
          <pbr>
            <metal>
              <roughness>0.05</roughness>
              <metalness>0.01</metalness>
            </metal>
          </pbr>
        </material>
      </visual>
      <collision name="sphere_8_collision">
        <pose>0.000000 0.000000 0.03125 0.000000 -0.000000 0.000000</pose>
        <geometry>
          <sphere>
            <radius>0.002</radius>
          </sphere>
        </geometry>
      </collision>
      <visual name="sphere_8_vis">
        <pose>0.000000 0.000000 0.03125 0.000000 -0.000000 0.000000</pose>
        <geometry>
          <sphere>
            <radius>0.002</radius>
          </sphere>
        </geometry>
        <material>
          <diffuse>0.6 0.6 0.0</diffuse>
          <specular>0.2 0.2 0.2</specular>
          <pbr>
            <metal>
              <roughness>0.05</roughness>
              <metalness>0.01</metalness>
            </metal>
          </pbr>
        </material>
      </visual>
    </link>
    <joint name="joint_1" type="ball">
      <pose>0.00000 0.000000 -0.03125 0.000000 0 0.000000</pose>
      <parent>link_1</parent>
      <child>link_2</child>
      <axis>
        <dynamics>
          <damping>1.0</damping>
          <spring_stiffness>1.0</spring_stiffness>
        </dynamics>
      </axis>
    </joint>
    <joint name="joint_2" type="ball">
      <pose>0.00000 0.000000 -0.03125 0.000000 0 0.000000</pose>
      <parent>link_2</parent>
      <child>link_3</child>
      <axis>
        <dynamics>
          <damping>1.0</damping>
          <spring_stiffness>1.0</spring_stiffness>
        </dynamics>
      </axis>
    </joint>
    <joint name="joint_3" type="ball">
      <pose>0.00000 0.000000 -0.03125 0.000000 0 0.000000</pose>
      <parent>link_3</parent>
      <child>link_4</child>
      <axis>
        <dynamics>
          <damping>1.0</damping>
          <spring_stiffness>1.0</spring_stiffness>
        </dynamics>
      </axis>
    </joint>
    <joint name="joint_4" type="ball">
      <pose>0.00000 0.000000 -0.03125 0.000000 0 0.000000</pose>
      <parent>link_4</parent>
      <child>link_5</child>
      <axis>
        <dynamics>
          <damping>1.0</damping>
          <spring_stiffness>1.0</spring_stiffness>
        </dynamics>
      </axis>
    </joint>
    <joint name="joint_5" type="ball">
      <pose>0.00000 0.000000 -0.03125 0.000000 0 0.000000</pose>
      <parent>link_5</parent>
      <child>link_6</child>
      <axis>
        <dynamics>
          <damping>1.0</damping>
          <spring_stiffness>1.0</spring_stiffness>
        </dynamics>
      </axis>
    </joint>
    <joint name="joint_6" type="ball">
      <pose>0.00000 0.000000 -0.03125 0.000000 0 0.000000</pose>
      <parent>link_6</parent>
      <child>link_7</child>
      <axis>
        <dynamics>
          <damping>1.0</damping>
          <spring_stiffness>1.0</spring_stiffness>
        </dynamics>
      </axis>
    </joint>
    <joint name="joint_7" type="ball">
      <pose>0.00000 0.000000 -0.03125 0.000000 0 0.000000</pose>
      <parent>link_7</parent>
      <child>link_8</child>
      <axis>
        <dynamics>
          <damping>1.0</damping>
          <spring_stiffness>1.0</spring_stiffness>
        </dynamics>
      </axis>
    </joint>
    <frame name="cable_mount_base">
      <pose>0 0 0 0 0 0</pose>
    </frame>
    <frame name="cable_mount_end">
      <pose>0.5 0 0 0 0 0</pose>
    </frame>
    <link name="cable_connection_0">
      <inertial>
        <pose>0.000000 0.000000 0.000000 0.000000 -0.000000 0.000000</pose>
        <mass>0.01</mass>
        <inertia>
          <ixx>0.010000</ixx>
          <ixy>0.000000</ixy>
          <ixz>0.000000</ixz>
          <iyy>0.010000</iyy>
          <iyz>0.000000</iyz>
          <izz>0.010000</izz>
        </inertia>
      </inertial>
      <pose relative_to="cable_mount_base">0 0 0 0 0 0</pose>
      <collision name="collision_0">
        <pose>-0.005099019513592785 0.002 0 0.19739555984988078 1.57079 0</pose>
        <geometry>
          <cylinder>
            <radius>0.001</radius>
            <length>0.01019803902718557</length>
          </cylinder>
        </geometry>
      </collision>
      <visual name="visual_0">
        <pose>-0.005099019513592785 0.002 0 0.19739555984988078 1.57079 0</pose>
        <geometry>
          <cylinder>
            <radius>0.001</radius>
            <length>0.01019803902718557</length>
          </cylinder>
        </geometry>
        <material>
          <diffuse>0.6 0.6 0.0</diffuse>
          <specular>0.2 0.2 0.2</specular>
          <pbr>
            <metal>
              <roughness>0.05</roughness>
              <metalness>0.01</metalness>
            </metal>
          </pbr>
        </material>
      </visual>
      <collision name="collision_1">
        <pose>-0.005099019513592785 -0.002 0 -0.19739555984988078 1.57079 0</pose>
        <geometry>
          <cylinder>
            <radius>0.001</radius>
            <length>0.01019803902718557</length>
          </cylinder>
        </geometry>
      </collision>
      <visual name="visual_1">
        <pose>-0.005099019513592785 -0.002 0 -0.19739555984988078 1.57079 0</pose>
        <geometry>
          <cylinder>
            <radius>0.001</radius>
            <length>0.01019803902718557</length>
          </cylinder>
        </geometry>
        <material>
          <diffuse>0.6 0.6 0.0</diffuse>
          <specular>0.2 0.2 0.2</specular>
          <pbr>
            <metal>
              <roughness>0.05</roughness>
              <metalness>0.01</metalness>
            </metal>
          </pbr>
        </material>
      </visual>
    </link>
    <link name="cable_connection_1">
      <inertial>
        <pose>0.000000 0.000000 0.000000 0.000000 -0.000000 0.000000</pose>
        <mass>0.01</mass>
        <inertia>
          <ixx>0.010000</ixx>
          <ixy>0.000000</ixy>
          <ixz>0.000000</ixz>
          <iyy>0.010000</iyy>
          <iyz>0.000000</iyz>
          <izz>0.010000</izz>
        </inertia>
      </inertial>
      <pose relative_to="cable_mount_end">0 0 0 0 0 0</pose>
      <collision name="collision_0">
        <pose>0.005099019513592785 -0.002 0 0.19739555984988078 1.57079 0</pose>
        <geometry>
          <cylinder>
            <radius>0.001</radius>
            <length>0.01019803902718557</length>
          </cylinder>
        </geometry>
      </collision>
      <visual name="visual_0">
        <pose>0.005099019513592785 -0.002 0 0.19739555984988078 1.57079 0</pose>
        <geometry>
          <cylinder>
            <radius>0.001</radius>
            <length>0.01019803902718557</length>
          </cylinder>
        </geometry>
        <material>
          <diffuse>0.6 0.6 0.0</diffuse>
          <specular>0.2 0.2 0.2</specular>
          <pbr>
            <metal>
              <roughness>0.05</roughness>
              <metalness>0.01</metalness>
            </metal>
          </pbr>
        </material>
      </visual>
      <collision name="collision_1">
        <pose>0.005099019513592785 0.002 0 -0.19739555984988078 1.57079 0</pose>
        <geometry>
          <cylinder>
            <radius>0.001</radius>
            <length>0.01019803902718557</length>
          </cylinder>
        </geometry>
      </collision>
      <visual name="visual_1">
        <pose>0.005099019513592785 0.002 0 -0.19739555984988078 1.57079 0</pose>
        <geometry>
          <cylinder>
            <radius>0.001</radius>
            <length>0.01019803902718557</length>
          </cylinder>
        </geometry>
        <material>
          <diffuse>0.6 0.6 0.0</diffuse>
          <specular>0.2 0.2 0.2</specular>
          <pbr>
            <metal>
              <roughness>0.05</roughness>
              <metalness>0.01</metalness>
            </metal>
          </pbr>
        </material>
      </visual>
    </link>
    <joint name="joint_connection_end_0" type="ball">
      <pose>0.00000 0.000000 0 0.000000 0 0.000000</pose>
      <parent>cable_end_0</parent>
      <child>cable_connection_0</child>
      <axis>
        <dynamics>
          <damping>1.0</damping>
          <spring_stiffness>1.0</spring_stiffness>
        </dynamics>
      </axis>
    </joint>
    <joint name="joint_connection_end_1" type="ball">
      <pose>0.00000 0.000000 0 0.000000 0 0.000000</pose>
      <parent>link_8</parent>
      <child>cable_connection_1</child>
      <axis>
        <dynamics>
          <damping>1.0</damping>
          <spring_stiffness>1.0</spring_stiffness>
        </dynamics>
      </axis>
    </joint>
  </model>
</sdf>
